Workbook

Sheet Mulai
A1: ENGLISH / 120-DAY TRACKER
A3: Dari nol menuju fondasi A1 dan pengenalan A2 • 4 fase × 30 hari • materi, praktik, dan review
A5: Tanggal mulai | C5: 46272 | E5: Jumlah hari | G5: =ROWS(Tracker!A6:A125) -> 120
A6: Tanggal akhir | C6: =C5+G5-1 -> 46391 | E6: Menit per sesi | G6: 55
A7: Ambang evaluasi | C7: 0.7 | E7: Ulang jika paham ≤ | G7: 2
A8: Total jam rencana | C8: =SUM(Tracker!K6:K125)/60 -> 110 | E8: Maks. nilai / aspek | G8: 5
A10: HARI SELESAI | C10: PROGRES HARI | E10: JAM AKTUAL | G10: PERLU DIULANG
A11: =COUNTIF(Tracker!J6:J125,"Selesai") -> 0 | C11: =A11/G5 -> 0 | E11: =SUM(Tracker!L6:L125)/60 -> 0 | G11: =COUNTIF(Tracker!Q6:Q125,"Ya") -> 0
A13: PROGRES PER FASE
A14: Fase | B14: Day awal | C14: Day akhir | D14: Selesai | E14: Total | F14: Progres | G14: Jam aktual | H14: Checkpoint
A15: 1 | B15: 1 | C15: 30 | D15: =COUNTIF(Tracker!J6:J35,"Selesai") -> 0 | E15: =ROWS(Tracker!A6:A35) -> 30 | F15: =D15/E15 -> 0 | G15: =SUM(Tracker!L6:L35)/60 -> 0 | H15: =COUNT(Evaluasi!H16:H20) -> 0
A16: 2 | B16: 31 | C16: 60 | D16: =COUNTIF(Tracker!J36:J65,"Selesai") -> 0 | E16: =ROWS(Tracker!A36:A65) -> 30 | F16: =D16/E16 -> 0 | G16: =SUM(Tracker!L36:L65)/60 -> 0 | H16: =COUNT(Evaluasi!H21:H25) -> 0
A17: 3 | B17: 61 | C17: 90 | D17: =COUNTIF(Tracker!J66:J95,"Selesai") -> 0 | E17: =ROWS(Tracker!A66:A95) -> 30 | F17: =D17/E17 -> 0 | G17: =SUM(Tracker!L66:L95)/60 -> 0 | H17: =COUNT(Evaluasi!H26:H30) -> 0
A18: 4 | B18: 91 | C18: 120 | D18: =COUNTIF(Tracker!J96:J125,"Selesai") -> 0 | E18: =ROWS(Tracker!A96:A125) -> 30 | F18: =D18/E18 -> 0 | G18: =SUM(Tracker!L96:L125)/60 -> 0 | H18: =COUNT(Evaluasi!H31:H35) -> 0
A20: CARA PAKAI
A21: 01 · Atur awal | C21: Tanggal default 7 Sep 2026 mengikuti jadwal belajar pukul 19.00 WIB yang sudah dibuat. Ubah sel biru C5 bila mulai di tanggal lain. Workbook tidak mengubah pengingat otomatis.
A22: 02 · Pilih Day | C22: Buka Belajar Hari Ini, isi Day 1–120. Materi, pengertian, contoh, artikel, video, dan tugas hari tersebut akan muncul otomatis.
A23: 03 · Latihan 55 menit | C23: 10 menit kosakata/review + 10 menit membaca + 15 menit video/listening + 10 menit speaking + 10 menit writing. Ini alokasi latihan, bukan durasi asli video.
A24: 04 · Tandai selesai | C24: Pada Tracker, pilih Selesai untuk setiap aktivitas. Satu hari selesai setelah kelimanya selesai. Isi menit aktual, tingkat paham, catatan, dan lokasi rekaman.
A25: 05 · Review jujur | C25: Paham 1 = belum paham; 2 = banyak bantuan; 3 = bisa dengan contoh; 4 = cukup mandiri; 5 = bisa menjelaskan. Perlu ulang tidak menghapus aktivitas yang selesai.
A26: 06 · Ukur kemajuan | C26: Isi Evaluasi pada hari yang ditentukan. Biarkan nilai kosong sebelum tes; angka 0 berarti sudah mencoba tetapi belum memenuhi kriteria.
A27: 07 · Tempo fleksibel | C27: 120 hari berarti 4 blok 30 hari, bukan persis empat bulan kalender. Target A1 kuat dan pengenalan A2 bukan jaminan kelulusan; ulang satu Day bila perlu.
A28: 08 · Sumber gratis | C28: Artikel dan halaman pelajaran utama tidak memerlukan pembelian tes atau kelas. Kursus/promosi berbayar tidak perlu diikuti. Video sengaja diulang dengan tugas berbeda.
A29: 09 · Jika masih sulit | C29: Baca penjelasan Indonesia dahulu, pilih 3–5 baris transkrip, lalu dengar potongan pendek. Tidak perlu memahami seluruh video; perlambat bila tersedia.
A30: 10 · Jika tautan gagal | C30: Buka Sumber dan cari judul persis di situs penerbit. Untuk VOA, coba tautan unduhan pada halaman. Akses/player dapat berubah; tidak perlu membeli layanan.
A32: HASIL YANG DITUJU
A33: Day 1–30: perkenalan, benda/keluarga, lokasi, waktu, dan rutinitas; teks sekitar 60 kata.
A34: Day 31–60: permintaan, kemampuan, kegiatan sekarang, menu, ajakan, pesan; teks sekitar 70 kata.
A35: Day 61–90: pengalaman lampau, rencana, perbandingan, saran; cerita sekitar 100 kata.
A36: Day 91–120: pengenalan perfect, strategi baca/dengar, komunikasi frontend; presentasi 2–3 menit dan teks 120–150 kata.
A38: Rencana dan contoh disusun khusus, bukan kurikulum resmi atau salinan penuh VOA/British Council. Artikel/transkrip ditautkan setiap Day. Belajar tidak perlu menunggu tes berbayar.

Sheet Tracker
A1: TRACKER / 120 HARI
A3: Isi sel biru: aktivitas, menit aktual, paham 1–5, tanggal selesai, catatan, dan bukti. Progres/status otomatis.
A5: Day | B5: Tanggal rencana | C5: Topik | D5: Kata / review | E5: Baca | F5: Video | G5: Speaking | H5: Writing | I5: Progres | J5: Status otomatis | K5: Target menit | L5: Menit aktual | M5: Paham 1–5 | N5: Tanggal selesai | O5: Catatan / kata sulit | P5: Bukti / lokasi rekaman | Q5: Perlu diulang?
A6: 1 | B6: =Mulai!$C$5+A6-1 -> 46272 | C6: Alphabet dan mengeja nama | D6: Belum | E6: Belum | F6: Belum | G6: Belum | H6: Belum | I6: =COUNTIF(D6:H6,"Selesai")/COLUMNS(D6:H6) -> 0 | J6: =IF(I6=1,"Selesai",IF(I6=0,"Belum mulai","Berjalan")) -> Belum mulai | K6: ='Rencana 120 Hari'!S6 -> 55 | Q6: =IF(M6="","",IF(M6<=Mulai!$G$7,"Ya","Tidak"))
A7: 2 | B7: =Mulai!$C$5+A7-1 -> 46273 | C7: Sapaan dan perkenalan | D7: Belum | E7: Belum | F7: Belum | G7: Belum | H7: Belum | I7: =COUNTIF(D7:H7,"Selesai")/COLUMNS(D7:H7) -> 0 | J7: =IF(I7=1,"Selesai",IF(I7=0,"Belum mulai","Berjalan")) -> Belum mulai | K7: ='Rencana 120 Hari'!S7 -> 55 | Q7: =IF(M7="","",IF(M7<=Mulai!$G$7,"Ya","Tidak"))
A8: 3 | B8: =Mulai!$C$5+A8-1 -> 46274 | C8: I, you, he, she, we, they, it | D8: Belum | E8: Belum | F8: Belum | G8: Belum | H8: Belum | I8: =COUNTIF(D8:H8,"Selesai")/COLUMNS(D8:H8) -> 0 | J8: =IF(I8=1,"Selesai",IF(I8=0,"Belum mulai","Berjalan")) -> Belum mulai | K8: ='Rencana 120 Hari'!S8 -> 55 | Q8: =IF(M8="","",IF(M8<=Mulai!$G$7,"Ya","Tidak"))
A9: 4 | B9: =Mulai!$C$5+A9-1 -> 46275 | C9: Am, is, are untuk identitas | D9: Belum | E9: Belum | F9: Belum | G9: Belum | H9: Belum | I9: =COUNTIF(D9:H9,"Selesai")/COLUMNS(D9:H9) -> 0 | J9: =IF(I9=1,"Selesai",IF(I9=0,"Belum mulai","Berjalan")) -> Belum mulai | K9: ='Rencana 120 Hari'!S9 -> 55 | Q9: =IF(M9="","",IF(M9<=Mulai!$G$7,"Ya","Tidak"))
A10: 5 | B10: =Mulai!$C$5+A10-1 -> 46276 | C10: Kalimat negatif: not | D10: Belum | E10: Belum | F10: Belum | G10: Belum | H10: Belum | I10: =COUNTIF(D10:H10,"Selesai")/COLUMNS(D10:H10) -> 0 | J10: =IF(I10=1,"Selesai",IF(I10=0,"Belum mulai","Berjalan")) -> Belum mulai | K10: ='Rencana 120 Hari'!S10 -> 55 | Q10: =IF(M10="","",IF(M10<=Mulai!$G$7,"Ya","Tidak"))
A11: 6 | B11: =Mulai!$C$5+A11-1 -> 46277 | C11: Pertanyaan Are you ...? | D11: Belum | E11: Belum | F11: Belum | G11: Belum | H11: Belum | I11: =COUNTIF(D11:H11,"Selesai")/COLUMNS(D11:H11) -> 0 | J11: =IF(I11=1,"Selesai",IF(I11=0,"Belum mulai","Berjalan")) -> Belum mulai | K11: ='Rencana 120 Hari'!S11 -> 55 | Q11: =IF(M11="","",IF(M11<=Mulai!$G$7,"Ya","Tidak"))
A12: 7 | B12: =Mulai!$C$5+A12-1 -> 46278 | C12: Review 1: identitas diri | D12: Belum | E12: Belum | F12: Belum | G12: Belum | H12: Belum | I12: =COUNTIF(D12:H12,"Selesai")/COLUMNS(D12:H12) -> 0 | J12: =IF(I12=1,"Selesai",IF(I12=0,"Belum mulai","Berjalan")) -> Belum mulai | K12: ='Rencana 120 Hari'!S12 -> 55 | Q12: =IF(M12="","",IF(M12<=Mulai!$G$7,"Ya","Tidak"))
A13: 8 | B13: =Mulai!$C$5+A13-1 -> 46279 | C13: What, who, where | D13: Belum | E13: Belum | F13: Belum | G13: Belum | H13: Belum | I13: =COUNTIF(D13:H13,"Selesai")/COLUMNS(D13:H13) -> 0 | J13: =IF(I13=1,"Selesai",IF(I13=0,"Belum mulai","Berjalan")) -> Belum mulai | K13: ='Rencana 120 Hari'!S13 -> 55 | Q13: =IF(M13="","",IF(M13<=Mulai!$G$7,"Ya","Tidak"))
A14: 9 | B14: =Mulai!$C$5+A14-1 -> 46280 | C14: My, your, his, her | D14: Belum | E14: Belum | F14: Belum | G14: Belum | H14: Belum | I14: =COUNTIF(D14:H14,"Selesai")/COLUMNS(D14:H14) -> 0 | J14: =IF(I14=1,"Selesai",IF(I14=0,"Belum mulai","Berjalan")) -> Belum mulai | K14: ='Rencana 120 Hari'!S14 -> 55 | Q14: =IF(M14="","",IF(M14<=Mulai!$G$7,"Ya","Tidak"))
A15: 10 | B15: =Mulai!$C$5+A15-1 -> 46281 | C15: Kata benda dan jamak | D15: Belum | E15: Belum | F15: Belum | G15: Belum | H15: Belum | I15: =COUNTIF(D15:H15,"Selesai")/COLUMNS(D15:H15) -> 0 | J15: =IF(I15=1,"Selesai",IF(I15=0,"Belum mulai","Berjalan")) -> Belum mulai | K15: ='Rencana 120 Hari'!S15 -> 55 | Q15: =IF(M15="","",IF(M15<=Mulai!$G$7,"Ya","Tidak"))
A16: 11 | B16: =Mulai!$C$5+A16-1 -> 46282 | C16: A, an, dan the | D16: Belum | E16: Belum | F16: Belum | G16: Belum | H16: Belum | I16: =COUNTIF(D16:H16,"Selesai")/COLUMNS(D16:H16) -> 0 | J16: =IF(I16=1,"Selesai",IF(I16=0,"Belum mulai","Berjalan")) -> Belum mulai | K16: ='Rencana 120 Hari'!S16 -> 55 | Q16: =IF(M16="","",IF(M16<=Mulai!$G$7,"Ya","Tidak"))
A17: 12 | B17: =Mulai!$C$5+A17-1 -> 46283 | C17: This, that, these, those | D17: Belum | E17: Belum | F17: Belum | G17: Belum | H17: Belum | I17: =COUNTIF(D17:H17,"Selesai")/COLUMNS(D17:H17) -> 0 | J17: =IF(I17=1,"Selesai",IF(I17=0,"Belum mulai","Berjalan")) -> Belum mulai | K17: ='Rencana 120 Hari'!S17 -> 55 | Q17: =IF(M17="","",IF(M17<=Mulai!$G$7,"Ya","Tidak"))
... A125: 120 | B125: =Mulai!$C$5+A125-1 -> 46391 | C125: Checkpoint akhir dan rencana berikutnya | D125: Belum | E125: Belum | F125: Belum | G125: Belum | H125: Belum | I125: =COUNTIF(D125:H125,"Selesai")/COLUMNS(D125:H125) -> 0 | J125: =IF(I125=1,"Selesai",IF(I125=0,"Belum mulai","Berjalan")) -> Belum mulai | K125: ='Rencana 120 Hari'!S125 -> 55 | Q125: =IF(M125="","",IF(M125<=Mulai!$G$7,"Ya","Tidak"))

Sheet Belajar Hari Ini
A1: BELAJAR HARI INI
A3: Ubah nomor Day pada sel biru. Materi mengikuti Rencana 120 Hari; catat progres pada Tracker.
A5: Pilih Day (1–120) | C5: 1 | E5: Tanggal rencana | G5: =Mulai!C5+C5-1 -> 46272
A7: TOPIK | C7: =INDEX('Rencana 120 Hari'!$D$6:$D$125,$C$5) -> Alphabet dan mengeja nama
A9: Target hari ini | C9: =INDEX('Rencana 120 Hari'!$E$6:$E$125,$C$5) -> Mengeja nama dan mengenali 26 nama huruf.
A11: Pengertian | C11: =INDEX('Rencana 120 Hari'!$G$6:$G$125,$C$5) -> Alphabet adalah kumpulan huruf. Spelling berarti menyebut huruf penyusun kata; nama huruf tidak selalu sama dengan bunyinya di dalam kata.
A15: Contoh + arti | C15: =INDEX('Rencana 120 Hari'!$H$6:$H$125,$C$5) -> My name is Sam. S-A-M. = Nama saya Sam, dieja S-A-M.
A18: Kosakata | C18: =INDEX('Rencana 120 Hari'!$I$6:$I$125,$C$5) -> name=nama; letter=huruf; spell=mengeja; first=pertama; last=terakhir
A21: Review · 10 menit | C21: =INDEX('Rencana 120 Hari'!$T$6:$T$125,$C$5) -> Pelajari 5 kata/frasa hari ini. Tutup catatan dan sebutkan kembali.
A24: Bacaan | C24: =INDEX('Rencana 120 Hari'!$J$6:$J$125,$C$5) -> Lesson 1: Welcome!
A26: Buka bacaan | C26: =HYPERLINK(INDEX('Rencana 120 Hari'!$K$6:$K$125,$C$5),INDEX('Rencana 120 Hari'!$K$6:$K$125,$C$5)) -> https://learningenglish.voanews.com/a/lets-learn-english-lesson-one/3111026.html
A28: Tugas baca · 10m | C28: =INDEX('Rencana 120 Hari'!$L$6:$L$125,$C$5) -> Baca Conversation dan bagian alphabet; cocokkan huruf nama sendiri.
A31: Video | C31: =INDEX('Rencana 120 Hari'!$M$6:$M$125,$C$5) -> Lesson 1: Welcome!
A33: Buka video | C33: =HYPERLINK(INDEX('Rencana 120 Hari'!$N$6:$N$125,$C$5),INDEX('Rencana 120 Hari'!$N$6:$N$125,$C$5)) -> https://learningenglish.voanews.com/a/lets-learn-english-lesson-one/3111026.html
A35: Tugas video · 15m | C35: =INDEX('Rencana 120 Hari'!$O$6:$O$125,$C$5) -> Perhatikan cara menyebut nama dan mengeja huruf. Mulai dengan transkrip bila perlu, lalu coba tanpa teks. Ambil cuplikan bila panjang; total latihan 15 menit.
A40: Speaking · 10m | C40: =INDEX('Rencana 120 Hari'!$P$6:$P$125,$C$5) -> Rekam nama dan eja 3 kali, 20–30 detik.
A43: Writing · 10m | C43: =INDEX('Rencana 120 Hari'!$Q$6:$Q$125,$C$5) -> Tulis 3 kalimat nama dan asal memakai contoh.
A46: Kriteria selesai | C46: =INDEX('Rencana 120 Hari'!$R$6:$R$125,$C$5) -> Nama dapat dieja tanpa melihat contoh.
A50: Target menit | C50: =INDEX('Rencana 120 Hari'!$S$6:$S$125,$C$5) -> 55 | E50: Progres Day ini | G50: =INDEX(Tracker!$I$6:$I$125,$C$5) -> 0
A52: Sumber dipakai ulang: sesi pertama mengenali makna, sesi berikutnya mendengar tanpa teks dan memproduksi kalimat. Durasi boleh 45–60 menit. Jika target menit di Mulai diubah, sesuaikan alokasi lima kegiatan secara manual.

Sheet Rencana 120 Hari
A1: 120 DAYS / RENCANA LENGKAP
A3: Database rencana. Untuk membaca satu hari tanpa menggulir ke samping, buka Belajar Hari Ini.
A5: Day | B5: Bulan | C5: Jenis sesi | D5: Topik | E5: Target hari ini | F5: ID konsep | G5: Pengertian (Indonesia) | H5: Contoh + arti | I5: Kosakata / review | J5: Judul bacaan | K5: URL bacaan | L5: Tugas baca · 10 menit | M5: Judul video | N5: URL video | O5: Tugas video · 15 menit | P5: Speaking · 10 menit | Q5: Writing · 10 menit | R5: Kriteria selesai | S5: Target menit | T5: Pengulangan · 10 menit
A6: 1 | B6: 1 | C6: Materi + praktik | D6: Alphabet dan mengeja nama | E6: Mengeja nama dan mengenali 26 nama huruf. | F6: alphabet | G6: ='Kamus Materi'!C6 -> Alphabet adalah kumpulan huruf. Spelling berarti menyebut huruf penyusun kata; nama huruf tidak selalu sama dengan bunyinya di dalam kata. | H6: ='Kamus Materi'!D6 -> My name is Sam. S-A-M. = Nama saya Sam, dieja S-A-M. | I6: name=nama; letter=huruf; spell=mengeja; first=pertama; last=terakhir | J6: Lesson 1: Welcome! | K6: https://learningenglish.voanews.com/a/lets-learn-english-lesson-one/3111026.html | L6: Baca Conversation dan bagian alphabet; cocokkan huruf nama sendiri. | M6: Lesson 1: Welcome! | N6: https://learningenglish.voanews.com/a/lets-learn-english-lesson-one/3111026.html | O6: Perhatikan cara menyebut nama dan mengeja huruf. Mulai dengan transkrip bila perlu, lalu coba tanpa teks. Ambil cuplikan bila panjang; total latihan 15 menit. | P6: Rekam nama dan eja 3 kali, 20–30 detik. | Q6: Tulis 3 kalimat nama dan asal memakai contoh. | R6: Nama dapat dieja tanpa melihat contoh. | S6: =Mulai!G6 -> 55 | T6: Pelajari 5 kata/frasa hari ini. Tutup catatan dan sebutkan kembali.
A7: 2 | B7: 1 | C7: Materi + praktik | D7: Sapaan dan perkenalan | E7: Memulai dan menutup perkenalan singkat. | F7: greeting | G7: ='Kamus Materi'!C7 -> Greeting berarti sapaan. Introduction adalah perkenalan singkat yang menyampaikan nama dan informasi diri dengan sopan. | H7: ='Kamus Materi'!D7 -> Hi, I am Sam. Nice to meet you. = Hai, saya Sam. Senang bertemu kamu. | I7: hello=halo; morning=pagi; meet=bertemu; friend=teman; welcome=selamat datang | J7: Lesson 2: Hello, I'm Anna! | K7: https://learningenglish.voanews.com/a/lets-learn-english-lesson-2-hello/3113733.html | L7: Baca 6 baris awal Conversation; tandai sapaan. | M7: Lesson 2: Hello, I'm Anna! | N7: https://learningenglish.voanews.com/a/lets-learn-english-lesson-2-hello/3113733.html | O7: Tangkap sapaan dan respons perkenalan. Mulai dengan transkrip bila perlu, lalu coba tanpa teks. Ambil cuplikan bila panjang; total latihan 15 menit. | P7: Mainkan dua peran yang saling menyapa, 30 detik. | Q7: Tulis dialog 4 baris dengan nama sendiri. | R7: Ada sapaan, nama, dan respons sopan. | S7: =Mulai!G6 -> 55 | T7: Ulang kata/frasa Day 1. Tambahkan target hari ini; sesi review tidak perlu kata baru.
A8: 3 | B8: 1 | C8: Materi + praktik | D8: I, you, he, she, we, they, it | E8: Memilih kata ganti untuk 7 subjek. | F8: pronoun | G8: ='Kamus Materi'!C8 -> Kata ganti subjek menggantikan orang atau benda yang menjadi pokok kalimat: I, you, we, they, he, she, it. | H8: ='Kamus Materi'!D8 -> She is a student. = Dia seorang mahasiswa. She menggantikan nama perempuan. | I8: I=saya; you=kamu; we=kami/kita; they=mereka; it=itu | J8: Personal pronouns | K8: https://learnenglish.britishcouncil.org/free-resources/grammar/english-grammar-reference/personal-pronouns | L8: Baca tabel subject pronouns saja; cocokkan dengan arti Indonesia. | M8: Lesson 2: Hello, I'm Anna! | N8: https://learningenglish.voanews.com/a/lets-learn-english-lesson-2-hello/3113733.html | O8: Cari kata I dan you pada dialog. Mulai dengan transkrip bila perlu, lalu coba tanpa teks. Ambil cuplikan bila panjang; total latihan 15 menit. | P8: Sebut 7 orang/benda lalu ganti dengan pronoun. | Q8: Tulis 7 kalimat pendek menggunakan pronoun dan be. | R8: Sedikitnya 5 dari 7 pronoun tepat. | S8: =Mulai!G6 -> 55 | T8: Ulang kata/frasa Day 2. Tambahkan target hari ini; sesi review tidak perlu kata baru.
A9: 4 | B9: 1 | C9: Materi + praktik | D9: Am, is, are untuk identitas | E9: Menghubungkan orang dengan identitas dan lokasi. | F9: be | G9: ='Kamus Materi'!C9 -> Am, is, dan are menghubungkan subjek dengan identitas, sifat, atau lokasi. Gunakan I am; he/she/it is; you/we/they are. | H9: ='Kamus Materi'!D9 -> I am ready. She is at home. = Saya siap. Dia di rumah. | I9: student=pelajar; worker=pekerja; home=rumah; here=di sini; ready=siap | J9: Present simple: 'to be' | K9: https://learnenglish.britishcouncil.org/free-resources/grammar/a1-a2/present-simple-be | L9: Baca tabel affirmative; kerjakan 5 butir latihan jika tersedia. | M9: Lesson 3: I'm Here! | N9: https://learningenglish.voanews.com/a/lets-learn-english-lesson-3-i-am-here/3126527.html | O9: Temukan bentuk I am dan lokasi. Mulai dengan transkrip bila perlu, lalu coba tanpa teks. Ambil cuplikan bila panjang; total latihan 15 menit. | P9: Ucapkan 6 kalimat tentang diri/keluarga. | Q9: Tulis 6 kalimat: 2 am, 2 is, 2 are. | R9: Minimal 5 kalimat memakai be yang tepat. | S9: =Mulai!G6 -> 55 | T9: Ulang kata/frasa Day 3. Tambahkan target hari ini; sesi review tidak perlu kata baru.
A10: 5 | B10: 1 | C10: Materi + praktik | D10: Kalimat negatif: not | E10: Mengubah kalimat be positif menjadi negatif. | F10: negative | G10: ='Kamus Materi'!C10 -> Untuk menyangkal kalimat yang memakai be, letakkan not setelah am/is/are. Bentuk singkat: is not → isn't; are not → aren't. | H10: ='Kamus Materi'!D10 -> I am not tired. = Saya tidak lelah. Bukan I not tired. | I10: not=tidak; tired=lelah; late=terlambat; happy=senang; alone=sendirian | J10: Present simple: 'to be' | K10: https://learnenglish.britishcouncil.org/free-resources/grammar/a1-a2/present-simple-be | L10: Baca bagian negative; tandai posisi not. | M10: Lesson 3: I'm Here! | N10: https://learningenglish.voanews.com/a/lets-learn-english-lesson-3-i-am-here/3126527.html | O10: Dengar kontraksi dan bandingkan dengan transkrip. Mulai dengan transkrip bila perlu, lalu coba tanpa teks. Ambil cuplikan bila panjang; total latihan 15 menit. | P10: Ubah 5 pernyataan menjadi penyangkalan. | Q10: Tulis 5 pasang kalimat positif-negatif. | R10: Not diletakkan setelah be. | S10: =Mulai!G6 -> 55 | T10: Ulang kata/frasa Day 4. Tambahkan target hari ini; sesi review tidak perlu kata baru.
A11: 6 | B11: 1 | C11: Materi + praktik | D11: Pertanyaan Are you ...? | E11: Bertanya identitas/keadaan dan menjawab singkat. | F11: questionbe | G11: ='Kamus Materi'!C11 -> Pertanyaan ya/tidak dengan be menempatkan am/is/are sebelum subjek. Jawaban singkat mengulang be yang sesuai. | H11: ='Kamus Materi'!D11 -> Are you busy? Yes, I am. = Apakah kamu sibuk? Ya. | I11: yes=ya; no=tidak; busy=sibuk; okay=baik-baik; sure=yakin | J11: Present simple: 'to be' | K11: https://learnenglish.britishcouncil.org/free-resources/grammar/a1-a2/present-simple-be | L11: Baca questions dan short answers. | M11: Lesson 2: Hello, I'm Anna! | N11: https://learningenglish.voanews.com/a/lets-learn-english-lesson-2-hello/3113733.html | O11: Dengar intonasi pertanyaan dan jawabannya. Mulai dengan transkrip bila perlu, lalu coba tanpa teks. Ambil cuplikan bila panjang; total latihan 15 menit. | P11: Buat tanya-jawab 5 kali dengan diri sendiri. | Q11: Tulis 5 pertanyaan dan jawaban singkat. | R11: Be berada sebelum subjek pada pertanyaan. | S11: =Mulai!G6 -> 55 | T11: Ulang kata/frasa Day 5. Tambahkan target hari ini; sesi review tidak perlu kata baru.
A12: 7 | B12: 1 | C12: Review / evaluasi | D12: Review 1: identitas diri | E12: Menyatukan sapaan, ejaan, dan be. | F12: review | G12: ='Kamus Materi'!C59 -> Active recall berarti mencoba mengingat tanpa melihat catatan. Spaced review adalah mengulang materi pada jeda berbeda; ulangi kesalahan lebih sering. | H12: ='Kamus Materi'!D59 -> Tutup catatan, sebutkan lima kata kemarin, kemudian periksa jawabannya. | I12: Ulang 10 kata Day 1–6; tanpa kata baru. | J12: Lesson 1: Welcome! | K12: https://learningenglish.voanews.com/a/lets-learn-english-lesson-one/3111026.html | L12: Tutup transkrip; ingat 5 ungkapan, kemudian periksa. | M12: Lesson 1: Welcome! | N12: https://learningenglish.voanews.com/a/lets-learn-english-lesson-one/3111026.html | O12: Tonton ulang untuk menangkap detail yang sebelumnya terlewat. Mulai dengan transkrip bila perlu, lalu coba tanpa teks. Ambil cuplikan bila panjang; total latihan 15 menit. | P12: Rekam perkenalan 30–45 detik tanpa membaca. | Q12: Tulis 5 kalimat diri sendiri dan 3 pertanyaan. | R12: Isi Evaluasi Day 7; catat 2 kesalahan utama. | S12: =Mulai!G6 -> 55 | T12: Ulang kata/frasa Day 6. Tambahkan target hari ini; sesi review tidak perlu kata baru.
A13: 8 | B13: 1 | C13: Materi + praktik | D13: What, who, where | E13: Membedakan pertanyaan orang, benda, dan lokasi. | F13: wh | G13: ='Kamus Materi'!C12 -> What menanyakan apa; who siapa; where di mana; when kapan; why mengapa; how bagaimana. Susunan setelahnya bergantung pada kata kerja. | H13: ='Kamus Materi'!D12 -> Where do you work? = Kamu bekerja di mana? | I13: what=apa; who=siapa; where=di mana; thing=benda; person=orang | J13: Question forms | K13: https://learnenglish.britishcouncil.org/free-resources/grammar/a1-a2/question-forms | L13: Baca contoh questions with be; jangan ambil semua tenses. | M13: Lesson 4: What Is It? | N13: https://learningenglish.voanews.com/a/lets-learn-english-lesson-4/3168920.html | O13: Dengarkan pertanyaan tentang benda. Mulai dengan transkrip bila perlu, lalu coba tanpa teks. Ambil cuplikan bila panjang; total latihan 15 menit. | P13: Ajukan 6 pertanyaan tentang benda/orang di rumah. | Q13: Tulis 2 pertanyaan per kata what/who/where. | R13: Masing-masing kata tanya digunakan sesuai makna. | S13: =Mulai!G6 -> 55 | T13: Ulang kata/frasa Day 7 dan Day 1. Tambahkan target hari ini; sesi review tidak perlu kata baru.
A14: 9 | B14: 1 | C14: Materi + praktik | D14: My, your, his, her | E14: Menyatakan pemilik benda dan hubungan keluarga. | F14: poss | G14: ='Kamus Materi'!C13 -> My, your, his, her, its, our, their menandai pemilik dan diikuti kata benda. Bedakan your (milikmu) dari you're (you are). | H14: ='Kamus Materi'!D13 -> This is my notebook. = Ini buku catatan saya. | I14: my=milik saya; your=milikmu; his=miliknya laki-laki; her=miliknya perempuan; our=milik kami | J14: Personal pronouns | K14: https://learnenglish.britishcouncil.org/free-resources/grammar/english-grammar-reference/personal-pronouns | L14: Baca bagian possessive adjectives yang ditautkan; jika tidak tampil, gunakan contoh di Kamus Materi. | M14: Lesson 12: Meet My Family | N14: https://learningenglish.voanews.com/a/lets-learn-english-lesson-12-meet-my-family/3301733.html | O14: Perhatikan cara mengenalkan anggota keluarga. Mulai dengan transkrip bila perlu, lalu coba tanpa teks. Ambil cuplikan bila panjang; total latihan 15 menit. | P14: Tunjukkan 5 benda dan sebut pemiliknya. | Q14: Tulis 6 frasa kepemilikan dan 3 kalimat. | R14: My/your/his/her diikuti noun. | S14: =Mulai!G6 -> 55 | T14: Ulang kata/frasa Day 8 dan Day 2. Tambahkan target hari ini; sesi review tidak perlu kata baru.
A15: 10 | B15: 1 | C15: Materi + praktik | D15: Kata benda dan jamak | E15: Membedakan satu benda dan lebih dari satu. | F15: noun | G15: ='Kamus Materi'!C14 -> Noun adalah kata benda, orang, tempat, atau gagasan. Plural berarti lebih dari satu; banyak kata menambah -s, tetapi ada bentuk tidak beraturan. | H15: ='Kamus Materi'!D14 -> one book → two books; one child → two children. | I15: book=buku; bag=tas; key=kunci; chair=kursi; child=anak | J15: Nouns: countable and uncountable | K15: https://learnenglish.britishcouncil.org/free-resources/grammar/a1-a2/nouns-countable-uncountable | L15: Baca countable nouns saja; cari singular/plural. | M15: Lesson 4: What Is It? | N15: https://learningenglish.voanews.com/a/lets-learn-english-lesson-4/3168920.html | O15: Tandai nama benda pada video. Mulai dengan transkrip bila perlu, lalu coba tanpa teks. Ambil cuplikan bila panjang; total latihan 15 menit. | P15: Sebut 5 benda tunggal dan versi jamaknya. | Q15: Tulis 8 pasangan tunggal-jamak. | R15: Minimal 6 dari 8 pasangan tepat. | S15: =Mulai!G6 -> 55 | T15: Ulang kata/frasa Day 9 dan Day 3. Tambahkan target hari ini; sesi review tidak perlu kata baru.
A16: 11 | B16: 1 | C16: Materi + praktik | D16: A, an, dan the | E16: Memilih a/an berdasar bunyi dan mengenalkan the. | F16: article | G16: ='Kamus Materi'!C15 -> A/an dipakai sebelum kata benda tunggal yang dapat dihitung dan belum spesifik. Pilih berdasarkan bunyi awal: a university, an hour. The menunjuk yang sudah tertentu. | H16: ='Kamus Materi'!D15 -> I have a pen. The pen is blue. = Saya punya pena. Pena itu biru. | I16: pen=pena; apple=apel; egg=telur; hour=jam; university=universitas | J16: Articles: 'a', 'an', 'the' | K16: https://learnenglish.britishcouncil.org/free-resources/grammar/a1-a2-grammar/articles-a-an-the | L16: Baca bagian a/an dan the; cukup contoh pertama. | M16: Lesson 4: What Is It? | N16: https://learningenglish.voanews.com/a/lets-learn-english-lesson-4/3168920.html | O16: Perhatikan penyebutan benda yang baru dikenalkan. Mulai dengan transkrip bila perlu, lalu coba tanpa teks. Ambil cuplikan bila panjang; total latihan 15 menit. | P16: Beri nama 6 benda dengan a/an. | Q16: Tulis 3 pasangan kalimat: benda baru lalu benda yang sama dengan the. | R16: Paham an hour dan a university. | S16: =Mulai!G6 -> 55 | T16: Ulang kata/frasa Day 10 dan Day 4. Tambahkan target hari ini; sesi review tidak perlu kata baru.
A17: 12 | B17: 1 | C17: Materi + praktik | D17: This, that, these, those | E17: Menunjuk benda dekat/jauh dan tunggal/jamak. | F17: demonstrative | G17: ='Kamus Materi'!C16 -> This/these menunjuk yang dekat; that/those yang jauh. This/that untuk tunggal, these/those untuk jamak. | H17: ='Kamus Materi'!D16 -> This is a cup. Those are books. = Ini cangkir. Itu buku-buku. | I17: this=ini tunggal; that=itu tunggal; these=ini jamak; those=itu jamak; near=dekat | J17: Lesson 4: What Is It? | K17: https://learningenglish.voanews.com/a/lets-learn-english-lesson-4/3168920.html | L17: Baca Conversation; gunakan materi worksheet sebagai pendamping. | M17: Lesson 4: What Is It? | N17: https://learningenglish.voanews.com/a/lets-learn-english-lesson-4/3168920.html | O17: Amati benda yang ditunjuk pembicara. Mulai dengan transkrip bila perlu, lalu coba tanpa teks. Ambil cuplikan bila panjang; total latihan 15 menit. | P17: Tunjuk 8 benda sambil memilih kata penunjuk. | Q17: Tulis 2 kalimat untuk setiap kata penunjuk. | R17: Minimal 6 dari 8 pilihan tepat. | S17: =Mulai!G6 -> 55 | T17: Ulang kata/frasa Day 11 dan Day 5. Tambahkan target hari ini; sesi review tidak perlu kata baru.
A18: 13 | B18: 1 | C18: Materi + praktik | D18: Sifat dan keadaan | E18: Menggambarkan benda dan cuaca dengan adjective. | F18: adjective | G18: ='Kamus Materi'!C17 -> Adjective adalah kata sifat yang menjelaskan orang atau benda. Biasanya berada sebelum noun atau setelah be; tidak berubah menjadi jamak. | H18: ='Kamus Materi'!D17 -> a small room; The room is small. = kamar kecil; Kamar itu kecil. | I18: hot=panas; cold=dingin; small=kecil; big=besar; clean=bersih | J18: Adjectives | K18: https://learnenglish.britishcouncil.org/free-resources/grammar/english-grammar-reference/adjectives | L18: Baca adjective sebelum noun dan setelah be. | M18: Lesson 9: Is It Cold? | N18: https://learningenglish.voanews.com/a/lets-learn-english-lesson-9-is-it-cold/3261789.html | O18: Dengar kata sifat cuaca. Mulai dengan transkrip bila perlu, lalu coba tanpa teks. Ambil cuplikan bila panjang; total latihan 15 menit. | P18: Ceritakan cuaca dan 3 benda di kamar. | Q18: Tulis 5 kalimat sifat tanpa menambah -s pada adjective. | R18: Setidaknya 4 kalimat susunannya tepat. | S18: =Mulai!G6 -> 55 | T18: Ulang kata/frasa Day 12 dan Day 6. Tambahkan target hari ini; sesi review tidak perlu kata baru.
A19: 14 | B19: 1 | C19: Review / evaluasi | D19: Review 2: benda di sekitarku | E19: Menggabungkan noun, article, possessive, adjective. | F19: review | G19: ='Kamus Materi'!C59 -> Active recall berarti mencoba mengingat tanpa melihat catatan. Spaced review adalah mengulang materi pada jeda berbeda; ulangi kesalahan lebih sering. | H19: ='Kamus Materi'!D59 -> Tutup catatan, sebutkan lima kata kemarin, kemudian periksa jawabannya. | I19: Ulang 10 kata Day 8–13; tanpa kata baru. | J19: Articles: 'a', 'an', 'the' | K19: https://learnenglish.britishcouncil.org/free-resources/grammar/a1-a2-grammar/articles-a-an-the | L19: Kerjakan ulang 5 butir artikel tanpa catatan. | M19: Lesson 4: What Is It? | N19: https://learningenglish.voanews.com/a/lets-learn-english-lesson-4/3168920.html | O19: Jeda sebelum jawaban; tebak benda yang dibahas. Mulai dengan transkrip bila perlu, lalu coba tanpa teks. Ambil cuplikan bila panjang; total latihan 15 menit. | P19: Deskripsikan 5 benda selama 45 detik. | Q19: Tulis 6 kalimat dan koreksi article/jamak. | R19: Isi Evaluasi Day 14; simpan rekaman. | S19: =Mulai!G6 -> 55 | T19: Ulang kata/frasa Day 13 dan Day 7. Tambahkan target hari ini; sesi review tidak perlu kata baru.
A20: 15 | B20: 1 | C20: Materi + praktik | D20: Angka 0–100 dan kontak | E20: Membaca angka dan informasi kontak dasar. | F20: number | G20: ='Kamus Materi'!C18 -> Cardinal numbers menyatakan jumlah (one, two). Ordinal numbers menyatakan urutan (first, second). Latih angka, jam, dan tanggal dalam konteks. | H20: ='Kamus Materi'!D18 -> The lesson starts at seven. = Pelajaran mulai pukul tujuh. | I20: zero=nol; ten=sepuluh; twenty=dua puluh; number=angka; phone=telepon | J20: Business cards | K20: https://learnenglish.britishcouncil.org/free-resources/reading/a1/business-cards | L20: Baca 2 business cards; cari nama, pekerjaan, dan nomor. | M20: Lesson 16: Where Are You From? | N20: https://learningenglish.voanews.com/a/lets-learn-english-lesson-16-where-are-you-from/3355849.html | O20: Tangkap asal orang; gunakan angka untuk informasi profil sendiri. Mulai dengan transkrip bila perlu, lalu coba tanpa teks. Ambil cuplikan bila panjang; total latihan 15 menit. | P20: Sebut angka acak dan nomor telepon fiktif. | Q20: Buat kartu nama fiktif 5 baris. | R20: Tidak memakai nomor pribadi saat latihan publik. | S20: =Mulai!G6 -> 55 | T20: Ulang kata/frasa Day 14 dan Day 8. Tambahkan target hari ini; sesi review tidak perlu kata baru.
A21: 16 | B21: 1 | C21: Materi + praktik | D21: Hari, tanggal, dan jam | E21: Menyebut hari dan jam belajar. | F21: number | G21: ='Kamus Materi'!C18 -> Cardinal numbers menyatakan jumlah (one, two). Ordinal numbers menyatakan urutan (first, second). Latih angka, jam, dan tanggal dalam konteks. | H21: ='Kamus Materi'!D18 -> The lesson starts at seven. = Pelajaran mulai pukul tujuh. | I21: Monday=Senin; Tuesday=Selasa; week=minggu; today=hari ini; tomorrow=besok | J21: A study timetable | K21: https://learnenglish.britishcouncil.org/free-resources/reading/a1/study-timetable | L21: Cari hari/jam pada study timetable. | M21: Lesson 17: Are You Free on Friday? | N21: https://learningenglish.voanews.com/a/are-you-free-on-friday-lets-learn-english/3355785.html | O21: Dengar hari dan waktu ajakan bertemu. Mulai dengan transkrip bila perlu, lalu coba tanpa teks. Ambil cuplikan bila panjang; total latihan 15 menit. | P21: Sebut jadwal 3 hari berikutnya. | Q21: Tulis jadwal belajar 5 baris. | R21: Bisa menyebut waktu sesi pukul 19.00. | S21: =Mulai!G6 -> 55 | T21: Ulang kata/frasa Day 15 dan Day 9. Tambahkan target hari ini; sesi review tidak perlu kata baru.
A22: 17 | B22: 1 | C22: Materi + praktik | D22: Ada: there is / there are | E22: Menjelaskan isi sebuah ruangan. | F22: there | G22: ='Kamus Materi'!C19 -> There is menyatakan keberadaan satu benda atau uncountable noun; there are untuk jamak. Maknanya ada, bukan terjemahan harfiah di sana. | H22: ='Kamus Materi'!D19 -> There is a desk. There are two chairs. = Ada meja dan dua kursi. | I22: room=kamar; desk=meja; door=pintu; window=jendela; floor=lantai | J22: Using 'there is' and 'there are' | K22: https://learnenglish.britishcouncil.org/free-resources/grammar/a1-a2/using-there-there-are | L22: Baca bentuk singular/plural dan latihan pertama. | M22: Lesson 6: Where Is the Gym? | N22: https://learningenglish.voanews.com/a/lets-learn-english-lesson-6-where-is-the-gym/3225958.html | O22: Amati lokasi fasilitas dalam video. Mulai dengan transkrip bila perlu, lalu coba tanpa teks. Ambil cuplikan bila panjang; total latihan 15 menit. | P22: Sebut 5 benda yang ada di kamar. | Q22: Tulis 3 there is dan 3 there are. | R22: Jumlah benda cocok dengan is/are. | S22: =Mulai!G6 -> 55 | T22: Ulang kata/frasa Day 16 dan Day 10. Tambahkan target hari ini; sesi review tidak perlu kata baru.
A23: 18 | B23: 1 | C23: Materi + praktik | D23: In, on, at untuk tempat | E23: Menyebut posisi orang/benda sederhana. | F23: place | G23: ='Kamus Materi'!C20 -> Preposition of place menunjukkan lokasi. In umumnya di dalam/area; on di atas permukaan; at pada suatu titik atau tempat kegiatan. | H23: ='Kamus Materi'!D20 -> The mouse is on the desk. = Mouse ada di atas meja. | I23: in=di dalam; on=di atas permukaan; at=di titik/tempat; table=meja; office=kantor | J23: Prepositions of place: 'in', 'on', 'at' | K23: https://learnenglish.britishcouncil.org/free-resources/grammar/a1-a2/prepositions-place | L23: Baca perbedaan in/on/at dan contoh lokasi. | M23: Lesson 5: Where Are You? | N23: https://learningenglish.voanews.com/a/lets-learn-english-lesson-5-where-are-you/3168971.html | O23: Dengar pertanyaan lokasi. Mulai dengan transkrip bila perlu, lalu coba tanpa teks. Ambil cuplikan bila panjang; total latihan 15 menit. | P23: Pindahkan 3 benda dan jelaskan letaknya. | Q23: Tulis 6 kalimat lokasi berdasarkan kamar. | R23: Minimal 4 lokasi dapat dipahami. | S23: =Mulai!G6 -> 55 | T23: Ulang kata/frasa Day 17 dan Day 11. Tambahkan target hari ini; sesi review tidak perlu kata baru.
A24: 19 | B24: 1 | C24: Materi + praktik | D24: Have / has dan barang milikmu | E24: Menyatakan kepemilikan memakai have/has. | F24: have | G24: ='Kamus Materi'!C21 -> Have/has menyatakan kepemilikan atau hubungan. I/you/we/they memakai have; he/she/it memakai has. Untuk pertanyaan biasa gunakan do/does + have. | H24: ='Kamus Materi'!D21 -> She has a laptop. Does she have a mouse? = Dia punya laptop. Apakah dia punya mouse? | I24: have=punya; laptop=laptop; cup=cangkir; kitchen=dapur; house=rumah | J24: Present simple: 'have got' | K24: https://learnenglish.britishcouncil.org/free-resources/grammar/a1-a2/present-simple-have-got | L24: Baca penjelasan have vs have got; fokus makna kepemilikan. | M24: Lesson 10: Come Over to My Place | N24: https://learningenglish.voanews.com/a/lets-learn-english-lesson-10/3285228.html | O24: Catat barang yang disebut di rumah. Mulai dengan transkrip bila perlu, lalu coba tanpa teks. Ambil cuplikan bila panjang; total latihan 15 menit. | P24: Sebut 3 barangmu dan 3 barang anggota keluarga. | Q24: Tulis 6 kalimat have/has. | R24: He/she memakai has pada kalimat positif. | S24: =Mulai!G6 -> 55 | T24: Ulang kata/frasa Day 18 dan Day 12. Tambahkan target hari ini; sesi review tidak perlu kata baru.
A25: 20 | B25: 1 | C25: Materi + praktik | D25: Keluarga dan possessive 's | E25: Mengenalkan keluarga dan benda miliknya. | F25: possessives | G25: ='Kamus Materi'!C22 -> Apostrophe + s menunjukkan pemilik: Sam's bag. Untuk jamak berakhiran s, apostrophe diletakkan setelah s. Bedakan 's pemilik dari is. | H25: ='Kamus Materi'!D22 -> This is my sister's phone. = Ini telepon saudara perempuan saya. | I25: mother=ibu; father=ayah; sister=saudara perempuan; brother=saudara laki-laki; family=keluarga | J25: Possessive 's | K25: https://learnenglish.britishcouncil.org/free-resources/grammar/a1-a2/possessive-s | L25: Baca aturan nama + 's dan contoh pertama. | M25: Lesson 12: Meet My Family | N25: https://learningenglish.voanews.com/a/lets-learn-english-lesson-12-meet-my-family/3301733.html | O25: Cari hubungan antaranggota keluarga. Mulai dengan transkrip bila perlu, lalu coba tanpa teks. Ambil cuplikan bila panjang; total latihan 15 menit. | P25: Kenalkan 3 anggota keluarga dalam 45 detik. | Q25: Tulis 5 kalimat menggunakan nama + 's. | R25: Bisa membedakan my sister dan my sister's bag. | S25: =Mulai!G6 -> 55 | T25: Ulang kata/frasa Day 19 dan Day 13. Tambahkan target hari ini; sesi review tidak perlu kata baru.
A26: 21 | B26: 1 | C26: Review / evaluasi | D26: Review 3: kamar dan keluarga | E26: Menggabungkan lokasi, kepemilikan, dan keluarga. | F26: review | G26: ='Kamus Materi'!C59 -> Active recall berarti mencoba mengingat tanpa melihat catatan. Spaced review adalah mengulang materi pada jeda berbeda; ulangi kesalahan lebih sering. | H26: ='Kamus Materi'!D59 -> Tutup catatan, sebutkan lima kata kemarin, kemudian periksa jawabannya. | I26: Ulang 10 kata Day 15–20; tanpa kata baru. | J26: Using 'there is' and 'there are' | K26: https://learnenglish.britishcouncil.org/free-resources/grammar/a1-a2/using-there-there-are | L26: Ulangi 5 soal there is/are lalu cek. | M26: Lesson 12: Meet My Family | N26: https://learningenglish.voanews.com/a/lets-learn-english-lesson-12-meet-my-family/3301733.html | O26: Dengar tanpa teks pertama kali; catat siapa yang dibahas. Mulai dengan transkrip bila perlu, lalu coba tanpa teks. Ambil cuplikan bila panjang; total latihan 15 menit. | P26: Tur kamar lisan 1 menit dengan 5 benda. | Q26: Tulis deskripsi rumah/keluarga 40–50 kata. | R26: Isi Evaluasi Day 21; koreksi 2 pola terlemah. | S26: =Mulai!G6 -> 55 | T26: Ulang kata/frasa Day 20 dan Day 14. Tambahkan target hari ini; sesi review tidak perlu kata baru.
A27: 22 | B27: 1 | C27: Materi + praktik | D27: Simple present: rutinitas saya | E27: Menceritakan kebiasaan memakai I + verb. | F27: present | G27: ='Kamus Materi'!C23 -> Bentuk ini menyatakan kebiasaan atau fakta. Pakai kata kerja dasar; untuk he/she/it tambahkan -s/-es sesuai ejaan. | H27: ='Kamus Materi'!D23 -> I build websites. She builds websites. = Saya/Dia membuat situs web. | I27: wake=bangun; eat=makan; drink=minum; work=bekerja; study=belajar | J27: Present simple | K27: https://learnenglish.britishcouncil.org/free-resources/grammar/a1-a2/present-simple | L27: Baca bagian rutinitas pada grammar explanation. | M27: Lesson 18: She Always Does That | N27: https://learningenglish.voanews.com/a/lets-learn-english-lesson-18-she-always-does-that/3357748.html | O27: Dengar kebiasaan yang berulang dalam video. Mulai dengan transkrip bila perlu, lalu coba tanpa teks. Ambil cuplikan bila panjang; total latihan 15 menit. | P27: Ucapkan 6 aktivitas harian berurutan. | Q27: Tulis 6 kalimat I dengan kata kerja dasar. | R27: Tidak menambahkan am sebelum kata kerja biasa. | S27: =Mulai!G6 -> 55 | T27: Ulang kata/frasa Day 21 dan Day 15. Tambahkan target hari ini; sesi review tidak perlu kata baru.
A28: 23 | B28: 1 | C28: Materi + praktik | D28: He/she + s/es | E28: Menceritakan kebiasaan orang lain. | F28: present | G28: ='Kamus Materi'!C23 -> Bentuk ini menyatakan kebiasaan atau fakta. Pakai kata kerja dasar; untuk he/she/it tambahkan -s/-es sesuai ejaan. | H28: ='Kamus Materi'!D23 -> I build websites. She builds websites. = Saya/Dia membuat situs web. | I28: start=mulai; finish=selesai; watch=menonton; read=membaca; sleep=tidur | J28: Present simple | K28: https://learnenglish.britishcouncil.org/free-resources/grammar/a1-a2/present-simple | L28: Baca aturan s/es dan y→ies. | M28: Lesson 18: She Always Does That | N28: https://learningenglish.voanews.com/a/lets-learn-english-lesson-18-she-always-does-that/3357748.html | O28: Cari kata kerja setelah he/she. Mulai dengan transkrip bila perlu, lalu coba tanpa teks. Ambil cuplikan bila panjang; total latihan 15 menit. | P28: Ubah 5 kalimat I menjadi she. | Q28: Tulis 6 kalimat rutinitas anggota keluarga. | R28: Minimal 5 kata kerja orang ketiga tepat. | S28: =Mulai!G6 -> 55 | T28: Ulang kata/frasa Day 22 dan Day 16. Tambahkan target hari ini; sesi review tidak perlu kata baru.
A29: 24 | B29: 1 | C29: Materi + praktik | D29: Don't / doesn't | E29: Menyatakan kebiasaan yang tidak dilakukan. | F29: do | G29: ='Kamus Materi'!C24 -> Do/does membantu pertanyaan dan penyangkalan simple present. Setelah does atau doesn't, kata kerja kembali ke bentuk dasar. | H29: ='Kamus Materi'!D24 -> Does he work here? He doesn't work here. Bukan does he works. | I29: do=kata bantu/melakukan; daily=harian; weekend=akhir pekan; early=awal; often=sering | J29: Present simple | K29: https://learnenglish.britishcouncil.org/free-resources/grammar/a1-a2/present-simple | L29: Baca bentuk negative; perhatikan verb dasar setelah doesn't. | M29: Lesson 19: When Do I Start? | N29: https://learningenglish.voanews.com/a/lets-learn-english-lesson-19-when-do-you-start/3357760.html | O29: Catat informasi jadwal kerja yang terdengar. Mulai dengan transkrip bila perlu, lalu coba tanpa teks. Ambil cuplikan bila panjang; total latihan 15 menit. | P29: Ucapkan 6 kebiasaan positif-negatif. | Q29: Tulis 3 don't dan 3 doesn't. | R29: Tidak menulis doesn't works. | S29: =Mulai!G6 -> 55 | T29: Ulang kata/frasa Day 23 dan Day 17. Tambahkan target hari ini; sesi review tidak perlu kata baru.
A30: 25 | B30: 1 | C30: Materi + praktik | D30: Do you ...? Does she ...? | E30: Membuat pertanyaan rutinitas. | F30: do | G30: ='Kamus Materi'!C24 -> Do/does membantu pertanyaan dan penyangkalan simple present. Setelah does atau doesn't, kata kerja kembali ke bentuk dasar. | H30: ='Kamus Materi'!D24 -> Does he work here? He doesn't work here. Bukan does he works. | I30: when=kapan; why=mengapa; how=bagaimana; usually=biasanya; every=setiap | J30: Question forms | K30: https://learnenglish.britishcouncil.org/free-resources/grammar/a1-a2/question-forms | L30: Baca present simple questions saja. | M30: Lesson 19: When Do I Start? | N30: https://learningenglish.voanews.com/a/lets-learn-english-lesson-19-when-do-you-start/3357760.html | O30: Tangkap pertanyaan mengenai mulai bekerja. Mulai dengan transkrip bila perlu, lalu coba tanpa teks. Ambil cuplikan bila panjang; total latihan 15 menit. | P30: Mainkan wawancara kebiasaan 6 tanya-jawab. | Q30: Tulis 3 do dan 3 does beserta jawaban. | R30: Pertanyaan memakai verb dasar. | S30: =Mulai!G6 -> 55 | T30: Ulang kata/frasa Day 24 dan Day 18. Tambahkan target hari ini; sesi review tidak perlu kata baru.
A31: 26 | B31: 1 | C31: Materi + praktik | D31: Always, often, sometimes, never | E31: Menjelaskan frekuensi tanpa angka pasti. | F31: frequency | G31: ='Kamus Materi'!C25 -> Always, usually, often, sometimes, never menyatakan seberapa sering. Umumnya sebelum kata kerja utama, tetapi setelah be. | H31: ='Kamus Materi'!D25 -> I usually study at night. I am often busy. = Saya biasanya belajar malam dan sering sibuk. | I31: always=selalu; usually=biasanya; often=sering; sometimes=kadang; never=tidak pernah | J31: Present simple | K31: https://learnenglish.britishcouncil.org/free-resources/grammar/a1-a2/present-simple | L31: Cari bagian adverbs of frequency pada contoh present simple. | M31: Lesson 18: She Always Does That | N31: https://learningenglish.voanews.com/a/lets-learn-english-lesson-18-she-always-does-that/3357748.html | O31: Hitung ungkapan kebiasaan yang tertangkap. Mulai dengan transkrip bila perlu, lalu coba tanpa teks. Ambil cuplikan bila panjang; total latihan 15 menit. | P31: Ceritakan 5 kebiasaan dengan frekuensi berbeda. | Q31: Tulis 5 kalimat frekuensi. | R31: Adverb ditempatkan wajar sebelum verb atau setelah be. | S31: =Mulai!G6 -> 55 | T31: Ulang kata/frasa Day 25 dan Day 19. Tambahkan target hari ini; sesi review tidak perlu kata baru.
A32: 27 | B32: 1 | C32: Materi + praktik | D32: At 7, on Monday, in September | E32: Menghubungkan kegiatan dengan waktu. | F32: timeprep | G32: ='Kamus Materi'!C26 -> At dipakai untuk jam; on untuk hari/tanggal; in untuk bulan/tahun atau bagian hari tertentu. Ada ungkapan khusus seperti at night. | H32: ='Kamus Materi'!D26 -> at 7 p.m.; on Monday; in September = pukul 7 malam; Senin; September. | I32: at=pada jam; on=pada hari; in=pada bulan; evening=sore/malam; night=malam | J32: Prepositions of time: 'at', 'in', 'on' | K32: https://learnenglish.britishcouncil.org/free-resources/grammar/a1-a2-grammar/prepositions-of-time-at-in-on | L32: Baca tabel at/on/in; catat at night. | M32: Lesson 17: Are You Free on Friday? | N32: https://learningenglish.voanews.com/a/are-you-free-on-friday-lets-learn-english/3355785.html | O32: Dengar rencana waktu bertemu. Mulai dengan transkrip bila perlu, lalu coba tanpa teks. Ambil cuplikan bila panjang; total latihan 15 menit. | P32: Sebut jadwal kerja/belajar selama 1 menit. | Q32: Tulis 6 kalimat waktu. | R32: Minimal 5 preposition waktu tepat. | S32: =Mulai!G6 -> 55 | T32: Ulang kata/frasa Day 26 dan Day 20. Tambahkan target hari ini; sesi review tidak perlu kata baru.
A33: 28 | B33: 1 | C33: Review / evaluasi | D33: Review 4: jadwalku | E33: Menjelaskan rutinitas dan bertanya jadwal. | F33: review | G33: ='Kamus Materi'!C59 -> Active recall berarti mencoba mengingat tanpa melihat catatan. Spaced review adalah mengulang materi pada jeda berbeda; ulangi kesalahan lebih sering. | H33: ='Kamus Materi'!D59 -> Tutup catatan, sebutkan lima kata kemarin, kemudian periksa jawabannya. | I33: Ulang kata Day 22–27; tanpa kata baru. | J33: A study timetable | K33: https://learnenglish.britishcouncil.org/free-resources/reading/a1/study-timetable | L33: Baca timetable; temukan 5 hari/jam tanpa terjemahan penuh. | M33: Lesson 18: She Always Does That | N33: https://learningenglish.voanews.com/a/lets-learn-english-lesson-18-she-always-does-that/3357748.html | O33: Tonton ulang dan tulis 3 kebiasaan yang terdengar. Mulai dengan transkrip bila perlu, lalu coba tanpa teks. Ambil cuplikan bila panjang; total latihan 15 menit. | P33: Ceritakan hari biasa selama 1 menit. | Q33: Tulis rutinitas 50 kata dan 4 pertanyaan. | R33: Isi Evaluasi Day 28; cek do/does dan s/es. | S33: =Mulai!G6 -> 55 | T33: Ulang kata/frasa Day 27 dan Day 21. Tambahkan target hari ini; sesi review tidak perlu kata baru.
A34: 29 | B34: 1 | C34: Materi + praktik | D34: Membaca pesan pendek | E34: Mengerti tujuan pesan dan memberi respons. | F34: email | G34: ='Kamus Materi'!C60 -> Pesan efektif menyebut tujuan, detail penting, dan tindakan yang diharapkan. Email lebih formal dapat memakai sapaan dan penutup yang sopan. | H34: ='Kamus Materi'!D60 -> Hi Ana, could you check the page? Thank you. = Hai Ana, bisa cek halamannya? Terima kasih. | I34: message=pesan; busy=sibuk; free=luang; later=nanti; sorry=maaf | J34: Text messages to a friend | K34: https://learnenglish.britishcouncil.org/free-resources/reading/a1/text-messages-friend | L34: Baca text messages; cari siapa, rencana apa, kapan. | M34: Lesson 8: Are You Busy? | N34: https://learningenglish.voanews.com/a/lets-learn-english-lesson-8-are-you-busy/3253185.html | O34: Dengar ungkapan sedang sibuk dan responsnya; belum perlu menguasai semua -ing. Mulai dengan transkrip bila perlu, lalu coba tanpa teks. Ambil cuplikan bila panjang; total latihan 15 menit. | P34: Mainkan percakapan ajakan 6 baris. | Q34: Tulis pesan ajakan belajar 30–40 kata. | R34: Pesan menyebut kegiatan dan waktu. | S34: =Mulai!G6 -> 55 | T34: Ulang kata/frasa Day 28 dan Day 22. Tambahkan target hari ini; sesi review tidak perlu kata baru.
A35: 30 | B35: 1 | C35: Review / evaluasi | D35: Checkpoint bulan 1: profil dan rutinitas | E35: Memeriksa fondasi, bukan mengejar skor tes resmi. | F35: rubric | G35: ='Kamus Materi'!C63 -> Rubrik adalah kriteria penilaian yang sama dari waktu ke waktu. Nilai latihan ini hanya alat belajar, bukan skor TOEFL atau sertifikasi CEFR. | H35: ='Kamus Materi'!D63 -> Bandingkan rekaman awal dan akhir: apakah pesan lebih lengkap dan mudah dipahami? | I35: Review 20 kata paling sulit bulan 1. | J35: Business cards | K35: https://learnenglish.britishcouncil.org/free-resources/reading/a1/business-cards | L35: Baca business cards; jawab nama, pekerjaan, kontak. | M35: Lesson 2: Hello, I'm Anna! | N35: https://learningenglish.voanews.com/a/lets-learn-english-lesson-2-hello/3113733.html | O35: Dengar ulang perkenalan; tulis 5 informasi yang dipahami. Mulai dengan transkrip bila perlu, lalu coba tanpa teks. Ambil cuplikan bila panjang; total latihan 15 menit. | P35: Rekam perkenalan + rutinitas 60 detik. | Q35: Tulis profil 60 kata dan koreksi memakai Kamus Materi. | R35: Isi Evaluasi Day 30; ulangi topik yang belum kuat. | S35: =Mulai!G6 -> 55 | T35: Ulang kata/frasa Day 29 dan Day 23. Tambahkan target hari ini; sesi review tidak perlu kata baru.
A36: 31 | B36: 2 | C36: Materi + praktik | D36: Me, him, her, us, them | E36: Membedakan pelaku dari penerima tindakan. | F36: object | G36: ='Kamus Materi'!C27 -> Me, you, him, her, it, us, them menggantikan penerima tindakan atau mengikuti preposition; berbeda dari kata ganti subjek. | H36: ='Kamus Materi'!D27 -> She helps me. I work with her. = Dia membantu saya. Saya bekerja dengannya. | I36: me=saya objek; him=dia laki-laki objek; her=dia perempuan objek; us=kami/kita objek; them=mereka objek | J36: Personal pronouns | K36: https://learnenglish.britishcouncil.org/free-resources/grammar/english-grammar-reference/personal-pronouns | L36: Baca object pronouns dan contoh setelah preposition. | M36: Lesson 12: Meet My Family | N36: https://learningenglish.voanews.com/a/lets-learn-english-lesson-12-meet-my-family/3301733.html | O36: Cari kata yang merujuk orang yang sama. Mulai dengan transkrip bila perlu, lalu coba tanpa teks. Ambil cuplikan bila panjang; total latihan 15 menit. | P36: Ucapkan 5 kalimat seseorang membantu orang lain. | Q36: Tulis 6 pasang subjek-objek, seperti she helps me. | R36: Minimal 5 objek dipilih tepat. | S36: =Mulai!G6 -> 55 | T36: Ulang kata/frasa Day 30 dan Day 24. Tambahkan target hari ini; sesi review tidak perlu kata baru.
A37: 32 | B37: 2 | C37: Materi + praktik | D37: Kemampuan: can / can't | E37: Menyatakan 3 kemampuan dan 2 keterbatasan. | F37: can | G37: ='Kamus Materi'!C28 -> Can menyatakan kemampuan atau izin sederhana, diikuti kata kerja dasar tanpa to dan tanpa -s. Bentuk negatifnya can't/cannot. | H37: ='Kamus Materi'!D28 -> I can write code. Can you help? = Saya bisa menulis kode. Bisa bantu? | I37: can=bisa; swim=berenang; cook=memasak; drive=mengemudi; code=menulis kode | J37: 'can' and 'could' | K37: https://learnenglish.britishcouncil.org/free-resources/grammar/english-grammar-reference/can-could | L37: Baca can untuk ability saja. | M37: Lesson 20: What Can You Do? | N37: https://learningenglish.voanews.com/a/lets-learn-english-lesson-20-what-can-you-do/3384429.html | O37: Catat kemampuan yang disebutkan. Mulai dengan transkrip bila perlu, lalu coba tanpa teks. Ambil cuplikan bila panjang; total latihan 15 menit. | P37: Rekam kemampuan diri 45 detik. | Q37: Tulis 5 can dan 3 can't. | R37: Tidak menulis can to atau can works. | S37: =Mulai!G6 -> 55 | T37: Ulang kata/frasa Day 31 dan Day 25. Tambahkan target hari ini; sesi review tidak perlu kata baru.
A38: 33 | B38: 2 | C38: Materi + praktik | D38: Bertanya kemampuan | E38: Mengajukan pertanyaan can dan jawaban singkat. | F38: can | G38: ='Kamus Materi'!C28 -> Can menyatakan kemampuan atau izin sederhana, diikuti kata kerja dasar tanpa to dan tanpa -s. Bentuk negatifnya can't/cannot. | H38: ='Kamus Materi'!D28 -> I can write code. Can you help? = Saya bisa menulis kode. Bisa bantu? | I38: help=membantu; speak=berbicara; write=menulis; draw=menggambar; sing=bernyanyi | J38: 'can' and 'could' | K38: https://learnenglish.britishcouncil.org/free-resources/grammar/english-grammar-reference/can-could | L38: Baca pola pertanyaan can. | M38: Lesson 20: What Can You Do? | N38: https://learningenglish.voanews.com/a/lets-learn-english-lesson-20-what-can-you-do/3384429.html | O38: Jeda sebelum respons dan tebak jawabannya. Mulai dengan transkrip bila perlu, lalu coba tanpa teks. Ambil cuplikan bila panjang; total latihan 15 menit. | P38: Mainkan 6 tanya-jawab kemampuan. | Q38: Tulis dialog 8 baris mengenai keterampilan. | R38: Can mendahului subjek dalam pertanyaan. | S38: =Mulai!G6 -> 55 | T38: Ulang kata/frasa Day 32 dan Day 26. Tambahkan target hari ini; sesi review tidak perlu kata baru.
A39: 34 | B39: 2 | C39: Materi + praktik | D39: Meminta bantuan dengan sopan | E39: Meminta pengulangan dan bantuan. | F39: request | G39: ='Kamus Materi'!C29 -> Can you/Could you + kata kerja dasar digunakan untuk meminta bantuan. Could biasanya terasa lebih sopan, bukan selalu menunjukkan masa lalu. | H39: ='Kamus Materi'!D29 -> Could you repeat that, please? = Bisa tolong diulangi? | I39: please=tolong; repeat=ulangi; explain=jelaskan; slowly=perlahan; again=lagi | J39: 'can' and 'could' | K39: https://learnenglish.britishcouncil.org/free-resources/grammar/english-grammar-reference/can-could | L39: Baca can/could untuk request; pilih 3 pola. | M39: Lesson 47: How Can I help? | N39: https://learningenglish.voanews.com/a/lets-learn-english-lesson-47-how-can-i-help/3737352.html | O39: Dengar ungkapan menawarkan/meminta bantuan. Mulai dengan transkrip bila perlu, lalu coba tanpa teks. Ambil cuplikan bila panjang; total latihan 15 menit. | P39: Latih 5 permintaan yang relevan saat kerja. | Q39: Tulis 5 permintaan memakai can/could. | R39: Permintaan jelas dan memakai verb dasar. | S39: =Mulai!G6 -> 55 | T39: Ulang kata/frasa Day 33 dan Day 27. Tambahkan target hari ini; sesi review tidak perlu kata baru.
A40: 35 | B40: 2 | C40: Materi + praktik | D40: Instruksi sederhana | E40: Memberi 4 langkah instruksi. | F40: imperative | G40: ='Kamus Materi'!C30 -> Kalimat perintah memakai kata kerja dasar tanpa subjek yang disebutkan. Tambahkan please agar lebih sopan; Don't + verb untuk larangan. | H40: ='Kamus Materi'!D30 -> Please open the file. Don't close the tab. = Buka berkasnya. Jangan tutup tab. | I40: open=buka; close=tutup; click=klik; wait=tunggu; check=periksa | J40: Notes at work | K40: https://learnenglish.britishcouncil.org/free-resources/reading/a1/notes-work | L40: Baca notes at work; cari tindakan yang diminta. | M40: Lesson 25: Watch Out! | N40: https://learningenglish.voanews.com/a/lets-learn-english-lesson-25-watch-out/3431138.html | O40: Perhatikan instruksi atau peringatan. Mulai dengan transkrip bila perlu, lalu coba tanpa teks. Ambil cuplikan bila panjang; total latihan 15 menit. | P40: Jelaskan cara membuka situs dalam 4 langkah. | Q40: Tulis 5 instruksi dan 2 larangan. | R40: Instruksi dimulai dengan verb dasar. | S40: =Mulai!G6 -> 55 | T40: Ulang kata/frasa Day 34 dan Day 28. Tambahkan target hari ini; sesi review tidak perlu kata baru.
A41: 36 | B41: 2 | C41: Materi + praktik | D41: Hobi: like dan enjoy | E41: Menyampaikan hobi dengan pola -ing. | F41: like | G41: ='Kamus Materi'!C33 -> Like/love/enjoy dapat mengungkapkan kesukaan. Untuk aktivitas, latih like/love/enjoy + verb-ing; enjoy tidak diikuti to + verb. | H41: ='Kamus Materi'!D33 -> I enjoy reading. = Saya menikmati membaca. Bukan enjoy to read. | I41: like=suka; enjoy=menikmati; music=musik; reading=membaca; walking=berjalan | J41: Verbs followed by '-ing' or infinitive | K41: https://learnenglish.britishcouncil.org/free-resources/grammar/a1-a2/verbs-followed-ing-or-infinitive | L41: Baca verbs followed by -ing; fokus enjoy/like. | M41: Lesson 15: I Love People-Watching! | N41: https://learningenglish.voanews.com/a/lets-learn-english-lesson-15-i-love-people-watching/3343720.html | O41: Tangkap aktivitas yang sedang diamati. Mulai dengan transkrip bila perlu, lalu coba tanpa teks. Ambil cuplikan bila panjang; total latihan 15 menit. | P41: Ceritakan 3 hobi dan satu alasan sederhana. | Q41: Tulis 6 kalimat like/enjoy + noun/-ing. | R41: Tidak menggunakan enjoy to. | S41: =Mulai!G6 -> 55 | T41: Ulang kata/frasa Day 35 dan Day 29. Tambahkan target hari ini; sesi review tidak perlu kata baru.
A42: 37 | B42: 2 | C42: Review / evaluasi | D42: Review 5: kemampuan dan bantuan | E42: Menggunakan can, request, object, dan instruksi. | F42: review | G42: ='Kamus Materi'!C59 -> Active recall berarti mencoba mengingat tanpa melihat catatan. Spaced review adalah mengulang materi pada jeda berbeda; ulangi kesalahan lebih sering. | H42: ='Kamus Materi'!D59 -> Tutup catatan, sebutkan lima kata kemarin, kemudian periksa jawabannya. | I42: Ulang kata Day 31–36; tanpa kata baru. | J42: 'can' and 'could' | K42: https://learnenglish.britishcouncil.org/free-resources/grammar/english-grammar-reference/can-could | L42: Kerjakan 5 contoh can/could; baca ulang kesalahan. | M42: Lesson 20: What Can You Do? | N42: https://learningenglish.voanews.com/a/lets-learn-english-lesson-20-what-can-you-do/3384429.html | O42: Dengar kemampuan dan rangkum 3 poin. Mulai dengan transkrip bila perlu, lalu coba tanpa teks. Ambil cuplikan bila panjang; total latihan 15 menit. | P42: Role-play minta bantuan dan menjelaskan kemampuan, 1 menit. | Q42: Tulis 8 baris dialog kerja sederhana. | R42: Isi Evaluasi Day 37; rekam ulang 2 kalimat bermasalah. | S42: =Mulai!G6 -> 55 | T42: Ulang kata/frasa Day 36 dan Day 30. Tambahkan target hari ini; sesi review tidak perlu kata baru.
...

Sheet Kamus Materi
A1: KAMUS MATERI
A3: 58 istilah dan pola dalam bahasa Indonesia. Contoh dibuat khusus untuk latihan; sumber pendamping memberi konteks tambahan.
A5: ID konsep | B5: Istilah / pola | C5: Pengertian sederhana | D5: Contoh dan arti | E5: URL pendamping | F5: Level pemakaian
A6: alphabet | B6: Alphabet & spelling | C6: Alphabet adalah kumpulan huruf. Spelling berarti menyebut huruf penyusun kata; nama huruf tidak selalu sama dengan bunyinya di dalam kata. | D6: My name is Sam. S-A-M. = Nama saya Sam, dieja S-A-M. | E6: https://learningenglish.voanews.com/a/lets-learn-english-lesson-one/3111026.html | F6: Dasar / strategi
A7: greeting | B7: Greetings & introduction | C7: Greeting berarti sapaan. Introduction adalah perkenalan singkat yang menyampaikan nama dan informasi diri dengan sopan. | D7: Hi, I am Sam. Nice to meet you. = Hai, saya Sam. Senang bertemu kamu. | E7: https://learningenglish.voanews.com/a/lets-learn-english-lesson-2-hello/3113733.html | F7: Dasar / strategi
A8: pronoun | B8: Subject pronoun | C8: Kata ganti subjek menggantikan orang atau benda yang menjadi pokok kalimat: I, you, we, they, he, she, it. | D8: She is a student. = Dia seorang mahasiswa. She menggantikan nama perempuan. | E8: https://learnenglish.britishcouncil.org/free-resources/grammar/english-grammar-reference/personal-pronouns | F8: Dasar / strategi
A9: be | B9: To be: am / is / are | C9: Am, is, dan are menghubungkan subjek dengan identitas, sifat, atau lokasi. Gunakan I am; he/she/it is; you/we/they are. | D9: I am ready. She is at home. = Saya siap. Dia di rumah. | E9: https://learnenglish.britishcouncil.org/free-resources/grammar/a1-a2/present-simple-be | F9: Dasar / strategi
A10: negative | B10: Kalimat negatif dengan be | C10: Untuk menyangkal kalimat yang memakai be, letakkan not setelah am/is/are. Bentuk singkat: is not → isn't; are not → aren't. | D10: I am not tired. = Saya tidak lelah. Bukan I not tired. | E10: https://learnenglish.britishcouncil.org/free-resources/grammar/a1-a2/present-simple-be | F10: Dasar / strategi
A11: questionbe | B11: Pertanyaan dengan be | C11: Pertanyaan ya/tidak dengan be menempatkan am/is/are sebelum subjek. Jawaban singkat mengulang be yang sesuai. | D11: Are you busy? Yes, I am. = Apakah kamu sibuk? Ya. | E11: https://learnenglish.britishcouncil.org/free-resources/grammar/a1-a2/present-simple-be | F11: Dasar / strategi
A12: wh | B12: Question words | C12: What menanyakan apa; who siapa; where di mana; when kapan; why mengapa; how bagaimana. Susunan setelahnya bergantung pada kata kerja. | D12: Where do you work? = Kamu bekerja di mana? | E12: https://learnenglish.britishcouncil.org/free-resources/grammar/a1-a2/question-forms | F12: Dasar / strategi
